<sdf version='1.6'>
  <world name='default'>
    <light name='sun' type='directional'>
      <cast_shadows>1</cast_shadows>
      <pose frame=''>0 0 10 0 -0 0</pose>
      <diffuse>0.8 0.8 0.8 1</diffuse>
      <specular>0.1 0.1 0.1 1</specular>
      <attenuation>
        <range>1000</range>
        <constant>0.9</constant>
        <linear>0.01</linear>
        <quadratic>0.001</quadratic>
      </attenuation>
      <direction>-0.5 0.5 -1</direction>
    </light>
    <model name='ground_plane'>
      <static>1</static>
      <link name='link'>
        <collision name='collision'>
          <geometry>
            <plane>
              <normal>0 0 1</normal>
              <size>100 100</size>
            </plane>
          </geometry>
          <surface>
            <friction>
              <ode>
                <mu>100</mu>
                <mu2>50</mu2>
              </ode>
              <torsional>
                <ode/>
              </torsional>
            </friction>
            <contact>
              <ode/>
            </contact>
            <bounce/>
          </surface>
          <max_contacts>10</max_contacts>
        </collision>
        <visual name='visual'>
          <cast_shadows>0</cast_shadows>
          <geometry>
            <plane>
              <normal>0 0 1</normal>
              <size>100 100</size>
            </plane>
          </geometry>
          <material>
            <script>
              <uri>file://media/materials/scripts/gazebo.material</uri>
              <name>Gazebo/Grey</name>
            </script>
          </material>
        </visual>
        <self_collide>0</self_collide>
        <kinematic>0</kinematic>
        <gravity>1</gravity>
      </link>
    </model>
    <gravity>0 0 -9.8</gravity>
    <magnetic_field>6e-06 2.3e-05 -4.2e-05</magnetic_field>
    <atmosphere type='adiabatic'/>
    <physics name='default_physics' default='0' type='ode'>
      <max_step_size>0.001</max_step_size>
      <real_time_factor>1</real_time_factor>
      <real_time_update_rate>1000</real_time_update_rate>
    </physics>
    <scene>
      <ambient>0.4 0.4 0.4 1</ambient>
      <background>0.7 0.7 0.7 1</background>
      <shadows>1</shadows>
    </scene>
    <spherical_coordinates>
      <surface_model>EARTH_WGS84</surface_model>
      <latitude_deg>0</latitude_deg>
      <longitude_deg>0</longitude_deg>
      <elevation>0</elevation>
      <heading_deg>0</heading_deg>
    </spherical_coordinates>
    <model name='robot'>
      <link name='base_link'>
        <pose frame=''>0 0 0 0 -0 0</pose>
        <inertial>
          <pose frame=''>0 0 0 0 -0 0</pose>
          <mass>2</mass>
          <inertia>
            <ixx>0.00305317</ixx>
            <ixy>0</ixy>
            <ixz>0</ixz>
            <iyy>0.00305317</iyy>
            <iyz>0</iyz>
            <izz>0.005625</izz>
          </inertia>
        </inertial>
        <collision name='base_link_collision'>
          <pose frame=''>0 0 0 0 -0 0</pose>
          <geometry>
            <mesh>
              <scale>1 1 1</scale>
              <uri>/home/ur3/catkin_mvilso2/src/final_proj/drivers/universal_robot/ur_description/meshes/ur3/collision/base.stl</uri>
            </mesh>
          </geometry>
          <max_contacts>10</max_contacts>
          <surface>
            <contact>
              <ode/>
            </contact>
            <bounce/>
            <friction>
              <torsional>
                <ode/>
              </torsional>
              <ode/>
            </friction>
          </surface>
        </collision>
        <visual name='base_link_visual'>
          <pose frame=''>0 0 0 0 -0 0</pose>
          <geometry>
            <mesh>
              <scale>1 1 1</scale>
              <uri>/home/ur3/catkin_mvilso2/src/final_proj/drivers/universal_robot/ur_description/meshes/ur3/visual/base.dae</uri>
            </mesh>
          </geometry>
        </visual>
        <self_collide>0</self_collide>
        <kinematic>0</kinematic>
        <gravity>1</gravity>
      </link>
      <joint name='world_joint' type='revolute'>
        <child>base_link</child>
        <parent>world</parent>
        <axis>
          <limit>
            <lower>0</lower>
            <upper>0</upper>
          </limit>
          <dynamics>
            <damping>0</damping>
            <friction>0</friction>
            <spring_reference>0</spring_reference>
            <spring_stiffness>0</spring_stiffness>
          </dynamics>
          <use_parent_model_frame>1</use_parent_model_frame>
          <xyz>0 0 1</xyz>
        </axis>
      </joint>
      <link name='shoulder_link'>
        <pose frame=''>0 0 0.1519 0 -0 0</pose>
        <inertial>
          <pose frame=''>0 0 0 0 -0 0</pose>
          <mass>2</mass>
          <inertia>
            <ixx>0.00809316</ixx>
            <ixy>0</ixy>
            <ixz>0</ixz>
            <iyy>0.00809316</iyy>
            <iyz>0</iyz>
            <izz>0.005625</izz>
          </inertia>
        </inertial>
        <collision name='shoulder_link_collision'>
          <pose frame=''>0 0 0 0 -0 0</pose>
          <geometry>
            <mesh>
              <scale>1 1 1</scale>
              <uri>/home/ur3/catkin_mvilso2/src/final_proj/drivers/universal_robot/ur_description/meshes/ur3/collision/shoulder.stl</uri>
            </mesh>
          </geometry>
          <surface>
            <contact>
              <ode/>
            </contact>
            <friction>
              <ode/>
              <torsional>
                <ode/>
              </torsional>
            </friction>
            <bounce/>
          </surface>
          <max_contacts>10</max_contacts>
        </collision>
        <visual name='shoulder_link_visual'>
          <pose frame=''>0 0 0 0 -0 0</pose>
          <geometry>
            <mesh>
              <scale>1 1 1</scale>
              <uri>/home/ur3/catkin_mvilso2/src/final_proj/drivers/universal_robot/ur_description/meshes/ur3/visual/shoulder.dae</uri>
            </mesh>
          </geometry>
          <material>
            <script>
              <uri>__default__</uri>
              <name>__default__</name>
            </script>
          </material>
        </visual>
        <gravity>1</gravity>
        <velocity_decay/>
        <self_collide>1</self_collide>
        <kinematic>0</kinematic>
      </link>
      <joint name='shoulder_pan_joint' type='revolute'>
        <child>shoulder_link</child>
        <parent>base_link</parent>
        <axis>
          <xyz>0 0 1</xyz>
          <limit>
            <lower>-6.28319</lower>
            <upper>6.28319</upper>
            <effort>330</effort>
            <velocity>2.16</velocity>
          </limit>
          <dynamics>
            <damping>0</damping>
            <friction>0</friction>
            <spring_reference>0</spring_reference>
            <spring_stiffness>0</spring_stiffness>
          </dynamics>
          <use_parent_model_frame>1</use_parent_model_frame>
        </axis>
      </joint>
      <link name='upper_arm_link'>
        <pose frame=''>0 0.1198 0.1519 3.14159 1.57079 3.14159</pose>
        <inertial>
          <pose frame=''>0 0 0.121825 0 -0 0</pose>
          <mass>3.42</mass>
          <inertia>
            <ixx>0.0217285</ixx>
            <ixy>0</ixy>
            <ixz>0</ixz>
            <iyy>0.0217285</iyy>
            <iyz>0</iyz>
            <izz>0.00961875</izz>
          </inertia>
        </inertial>
        <collision name='upper_arm_link_collision'>
          <pose frame=''>0 0 0 0 -0 0</pose>
          <geometry>
            <mesh>
              <scale>1 1 1</scale>
              <uri>/home/ur3/catkin_mvilso2/src/final_proj/drivers/universal_robot/ur_description/meshes/ur3/collision/upperarm.stl</uri>
            </mesh>
          </geometry>
          <surface>
            <contact>
              <ode/>
            </contact>
            <friction>
              <ode/>
              <torsional>
                <ode/>
              </torsional>
            </friction>
            <bounce/>
          </surface>
          <max_contacts>10</max_contacts>
        </collision>
        <visual name='upper_arm_link_visual'>
          <pose frame=''>0 0 0 0 -0 0</pose>
          <geometry>
            <mesh>
              <scale>1 1 1</scale>
              <uri>/home/ur3/catkin_mvilso2/src/final_proj/drivers/universal_robot/ur_description/meshes/ur3/visual/upperarm.dae</uri>
            </mesh>
          </geometry>
          <material>
            <script>
              <uri>__default__</uri>
              <name>__default__</name>
            </script>
          </material>
        </visual>
        <gravity>1</gravity>
        <velocity_decay/>
        <self_collide>1</self_collide>
        <kinematic>0</kinematic>
      </link>
      <joint name='shoulder_lift_joint' type='revolute'>
        <child>upper_arm_link</child>
        <parent>shoulder_link</parent>
        <axis>
          <xyz>0 1 0</xyz>
          <limit>
            <lower>-6.28319</lower>
            <upper>6.28319</upper>
            <effort>330</effort>
            <velocity>2.16</velocity>
          </limit>
          <dynamics>
            <damping>0</damping>
            <friction>0</friction>
            <spring_reference>0</spring_reference>
            <spring_stiffness>0</spring_stiffness>
          </dynamics>
          <use_parent_model_frame>1</use_parent_model_frame>
        </axis>
      </joint>
      <link name='forearm_link'>
        <pose frame=''>0.24365 0.0273 0.1519 3.14159 1.57079 3.14159</pose>
        <inertial>
          <pose frame=''>0 0 0.106625 0 -0 0</pose>
          <mass>1.26</mass>
          <inertia>
            <ixx>0.00654681</ixx>
            <ixy>0</ixy>
            <ixz>0</ixz>
            <iyy>0.00654681</iyy>
            <iyz>0</iyz>
            <izz>0.00354375</izz>
          </inertia>
        </inertial>
        <collision name='forearm_link_collision'>
          <pose frame=''>0 0 0 0 -0 0</pose>
          <geometry>
            <mesh>
              <scale>1 1 1</scale>
              <uri>/home/ur3/catkin_mvilso2/src/final_proj/drivers/universal_robot/ur_description/meshes/ur3/collision/forearm.stl</uri>
            </mesh>
          </geometry>
          <surface>
            <contact>
              <ode/>
            </contact>
            <friction>
              <ode/>
              <torsional>
                <ode/>
              </torsional>
            </friction>
            <bounce/>
          </surface>
          <max_contacts>10</max_contacts>
        </collision>
        <visual name='forearm_link_visual'>
          <pose frame=''>0 0 0 0 -0 0</pose>
          <geometry>
            <mesh>
              <scale>1 1 1</scale>
              <uri>/home/ur3/catkin_mvilso2/src/final_proj/drivers/universal_robot/ur_description/meshes/ur3/visual/forearm.dae</uri>
            </mesh>
          </geometry>
          <material>
            <script>
              <uri>__default__</uri>
              <name>__default__</name>
            </script>
          </material>
        </visual>
        <gravity>1</gravity>
        <velocity_decay/>
        <self_collide>1</self_collide>
        <kinematic>0</kinematic>
      </link>
      <joint name='elbow_joint' type='revolute'>
        <child>forearm_link</child>
        <parent>upper_arm_link</parent>
        <axis>
          <xyz>0 1 0</xyz>
          <limit>
            <lower>-3.14159</lower>
            <upper>3.14159</upper>
            <effort>150</effort>
            <velocity>3.15</velocity>
          </limit>
          <dynamics>
            <damping>0</damping>
            <friction>0</friction>
            <spring_reference>0</spring_reference>
            <spring_stiffness>0</spring_stiffness>
          </dynamics>
          <use_parent_model_frame>1</use_parent_model_frame>
        </axis>
      </joint>
      <link name='wrist_1_link'>
        <pose frame=''>0.4569 0.0273 0.1519 3.14159 -0 3.14159</pose>
        <inertial>
          <pose frame=''>0 0.08505 0 0 -0 0</pose>
          <mass>0.8</mass>
          <inertia>
            <ixx>0.002085</ixx>
            <ixy>0</ixy>
            <ixz>0</ixz>
            <iyy>0.002085</iyy>
            <iyz>0</iyz>
            <izz>0.00225</izz>
          </inertia>
        </inertial>
        <collision name='wrist_1_link_collision'>
          <pose frame=''>0 0 0 0 -0 0</pose>
          <geometry>
            <mesh>
              <scale>1 1 1</scale>
              <uri>/home/ur3/catkin_mvilso2/src/final_proj/drivers/universal_robot/ur_description/meshes/ur3/collision/wrist1.stl</uri>
            </mesh>
          </geometry>
          <surface>
            <contact>
              <ode/>
            </contact>
            <friction>
              <ode/>
              <torsional>
                <ode/>
              </torsional>
            </friction>
            <bounce/>
          </surface>
          <max_contacts>10</max_contacts>
        </collision>
        <visual name='wrist_1_link_visual'>
          <pose frame=''>0 0 0 0 -0 0</pose>
          <geometry>
            <mesh>
              <scale>1 1 1</scale>
              <uri>/home/ur3/catkin_mvilso2/src/final_proj/drivers/universal_robot/ur_description/meshes/ur3/visual/wrist1.dae</uri>
            </mesh>
          </geometry>
          <material>
            <script>
              <uri>__default__</uri>
              <name>__default__</name>
            </script>
          </material>
        </visual>
        <gravity>1</gravity>
        <velocity_decay/>
        <self_collide>1</self_collide>
        <kinematic>0</kinematic>
      </link>
      <joint name='wrist_1_joint' type='revolute'>
        <child>wrist_1_link</child>
        <parent>forearm_link</parent>
        <axis>
          <xyz>0 1 0</xyz>
          <limit>
            <lower>-6.28319</lower>
            <upper>6.28319</upper>
            <effort>54</effort>
            <velocity>3.2</velocity>
          </limit>
          <dynamics>
            <damping>0</damping>
            <friction>0</friction>
            <spring_reference>0</spring_reference>
            <spring_stiffness>0</spring_stiffness>
          </dynamics>
          <use_parent_model_frame>1</use_parent_model_frame>
        </axis>
      </joint>
      <link name='wrist_2_link'>
        <pose frame=''>0.4569 0.11235 0.1519 3.14159 -0 3.14159</pose>
        <inertial>
          <pose frame=''>0 0 0.08535 0 -0 0</pose>
          <mass>0.8</mass>
          <inertia>
            <ixx>0.002085</ixx>
            <ixy>0</ixy>
            <ixz>0</ixz>
            <iyy>0.002085</iyy>
            <iyz>0</iyz>
            <izz>0.00225</izz>
          </inertia>
        </inertial>
        <collision name='wrist_2_link_collision'>
          <pose frame=''>0 0 0 0 -0 0</pose>
          <geometry>
            <mesh>
              <scale>1 1 1</scale>
              <uri>/home/ur3/catkin_mvilso2/src/final_proj/drivers/universal_robot/ur_description/meshes/ur3/collision/wrist2.stl</uri>
            </mesh>
          </geometry>
          <surface>
            <contact>
              <ode/>
            </contact>
            <friction>
              <ode/>
              <torsional>
                <ode/>
              </torsional>
            </friction>
            <bounce/>
          </surface>
          <max_contacts>10</max_contacts>
        </collision>
        <visual name='wrist_2_link_visual'>
          <pose frame=''>0 0 0 0 -0 0</pose>
          <geometry>
            <mesh>
              <scale>1 1 1</scale>
              <uri>/home/ur3/catkin_mvilso2/src/final_proj/drivers/universal_robot/ur_description/meshes/ur3/visual/wrist2.dae</uri>
            </mesh>
          </geometry>
          <material>
            <script>
              <uri>__default__</uri>
              <name>__default__</name>
            </script>
          </material>
        </visual>
        <gravity>1</gravity>
        <velocity_decay/>
        <self_collide>1</self_collide>
        <kinematic>0</kinematic>
      </link>
      <joint name='wrist_2_joint' type='revolute'>
        <child>wrist_2_link</child>
        <parent>wrist_1_link</parent>
        <axis>
          <xyz>0 0 -1</xyz>
          <limit>
            <lower>-6.28319</lower>
            <upper>6.28319</upper>
            <effort>54</effort>
            <velocity>3.2</velocity>
          </limit>
          <dynamics>
            <damping>0</damping>
            <friction>0</friction>
            <spring_reference>0</spring_reference>
            <spring_stiffness>0</spring_stiffness>
          </dynamics>
          <use_parent_model_frame>1</use_parent_model_frame>
        </axis>
      </joint>
      <link name='wrist_3_link'>
        <pose frame=''>0.4569 0.11235 0.06655 3.14159 -0 3.14159</pose>
        <inertial>
          <pose frame=''>0 0.061906 0 1.5708 -0 0</pose>
          <mass>0.3501</mass>
          <inertia>
            <ixx>0.000136317</ixx>
            <ixy>0</ixy>
            <ixz>0</ixz>
            <iyy>0.000136317</iyy>
            <iyz>1.95808e-19</iyz>
            <izz>0.00017921</izz>
          </inertia>
        </inertial>
        <collision name='wrist_3_link_collision'>
          <pose frame=''>0 0 0 0 -0 0</pose>
          <geometry>
            <mesh>
              <scale>1 1 1</scale>
              <uri>/home/ur3/catkin_mvilso2/src/final_proj/drivers/universal_robot/ur_description/meshes/ur3/collision/wrist3.stl</uri>
            </mesh>
          </geometry>
          <surface>
            <contact>
              <ode/>
            </contact>
            <friction>
              <ode/>
              <torsional>
                <ode/>
              </torsional>
            </friction>
            <bounce/>
          </surface>
          <max_contacts>10</max_contacts>
        </collision>
        <collision name='wrist_3_link_fixed_joint_lump__ee_link_collision_1'>
          <pose frame=''>-0 0.0719 0 0 -0 1.5708</pose>
          <geometry>
            <box>
              <size>0.01 0.01 0.01</size>
            </box>
          </geometry>
          <surface>
            <contact>
              <ode/>
            </contact>
            <friction>
              <ode/>
              <torsional>
                <ode/>
              </torsional>
            </friction>
            <bounce/>
          </surface>
          <max_contacts>10</max_contacts>
        </collision>
        <visual name='wrist_3_link_visual'>
          <pose frame=''>0 0 0 0 -0 0</pose>
          <geometry>
            <mesh>
              <scale>1 1 1</scale>
              <uri>/home/ur3/catkin_mvilso2/src/final_proj/drivers/universal_robot/ur_description/meshes/ur3/visual/wrist3.dae</uri>
            </mesh>
          </geometry>
          <material>
            <script>
              <uri>__default__</uri>
              <name>__default__</name>
            </script>
          </material>
        </visual>
        <visual name='wrist_3_link_fixed_joint_lump__ee_link_visual_1'>
          <pose frame=''>0 0.0819 0 0 -0 1.5708</pose>
          <geometry>
            <mesh>
              <scale>1 1 1</scale>
              <uri>/home/ur3/catkin_mvilso2/src/final_proj/drivers/universal_robot/ur_description/meshes/ur3/visual/UR3SuctionCupMount.stl</uri>
            </mesh>
          </geometry>
          <material>
            <script>
              <name>Gazebo/Grey</name>
              <uri>file://media/materials/scripts/gazebo.material</uri>
            </script>
          </material>
        </visual>
        <velocity_decay/>
        <velocity_decay/>
        <gravity>1</gravity>
        <velocity_decay/>
        <self_collide>1</self_collide>
        <kinematic>0</kinematic>
      </link>
      <joint name='wrist_3_joint' type='revolute'>
        <child>wrist_3_link</child>
        <parent>wrist_2_link</parent>
        <axis>
          <xyz>0 1 0</xyz>
          <limit>
            <lower>-6.28319</lower>
            <upper>6.28319</upper>
            <effort>54</effort>
            <velocity>3.2</velocity>
          </limit>
          <dynamics>
            <damping>0</damping>
            <friction>0</friction>
            <spring_reference>0</spring_reference>
            <spring_stiffness>0</spring_stiffness>
          </dynamics>
          <use_parent_model_frame>1</use_parent_model_frame>
        </axis>
      </joint>
      <link name='vacuum_gripper'>
        <pose frame=''>0.5104 0.25325 0.06655 3e-06 -1.57079 -1.5708</pose>
        <inertial>
          <pose frame=''>0 0 0 0 -0 0</pose>
          <mass>0.0001</mass>
          <inertia>
            <ixx>1e-08</ixx>
            <ixy>0</ixy>
            <ixz>0</ixz>
            <iyy>1e-08</iyy>
            <iyz>0</iyz>
            <izz>1e-08</izz>
          </inertia>
        </inertial>
        <visual name='vacuum_gripper_visual'>
          <pose frame=''>0 0 0 0 -0 0</pose>
          <geometry>
            <cylinder>
              <length>0.01</length>
              <radius>0.005</radius>
            </cylinder>
          </geometry>
          <material>
            <script>
              <name>Gazebo/Black</name>
              <uri>file://media/materials/scripts/gazebo.material</uri>
            </script>
          </material>
        </visual>
        <gravity>1</gravity>
        <velocity_decay/>
        <self_collide>0</self_collide>
        <kinematic>0</kinematic>
      </link>
      <joint name='gripper_joint' type='revolute'>
        <child>vacuum_gripper</child>
        <parent>wrist_3_link</parent>
        <axis>
          <xyz>0 -4e-06 1</xyz>
          <limit>
            <lower>0</lower>
            <upper>0</upper>
            <effort>50</effort>
            <velocity>50</velocity>
          </limit>
          <dynamics>
            <damping>0</damping>
            <friction>10</friction>
            <spring_reference>0</spring_reference>
            <spring_stiffness>0</spring_stiffness>
          </dynamics>
          <use_parent_model_frame>1</use_parent_model_frame>
        </axis>
      </joint>
      <plugin name='ros_control' filename='libgazebo_ros_control.so'>
        <legacyModeNS>true</legacyModeNS>
        <robotNamespace>/</robotNamespace>
      </plugin>
      <static>0</static>
      <plugin name='gazebo_ros_vacuum_gripper' filename='libgazebo_ros_vacuum_gripper.so'>
        <robotNamespace>/gripper</robotNamespace>
        <bodyName>vacuum_gripper</bodyName>
        <topicName>grasping</topicName>
        <maxForce>0.5</maxForce>
        <maxDistance>0.01</maxDistance>
        <minDistance>0.01</minDistance>
      </plugin>
      <pose frame=''>-0.15 0.15 0.01 0 -0 0</pose>
    </model>
    <model name='plate'>
      <link name='base_link'>
        <pose frame=''>0 0 0 0 -0 0</pose>
        <inertial>
          <pose frame=''>0 0 0 0 -0 0</pose>
          <mass>0.0225</mass>
          <inertia>
            <ixx>3.79215e-06</ixx>
            <ixy>0</ixy>
            <ixz>0</ixz>
            <iyy>3.79215e-06</iyy>
            <iyz>0</iyz>
            <izz>3.79215e-06</izz>
          </inertia>
        </inertial>
        <collision name='base_link_collision'>
          <pose frame=''>0 0 0 0 -0 0</pose>
          <geometry>
            <box>
              <size>0.001 0.001 0.01</size>
            </box>
          </geometry>
          <surface>
            <contact>
              <ode/>
            </contact>
            <friction>
              <ode/>
              <torsional>
                <ode/>
              </torsional>
            </friction>
            <bounce/>
          </surface>
          <max_contacts>10</max_contacts>
        </collision>
        <visual name='base_link_visual'>
          <pose frame=''>0 0 0 0 -0 0</pose>
          <geometry>
            <box>
              <size>0.3 0.3 0.01</size>
            </box>
          </geometry>
          <material>
            <script>
              <name>Gazebo/Grey</name>
              <uri>file://media/materials/scripts/gazebo.material</uri>
            </script>
          </material>
        </visual>
        <gravity>1</gravity>
        <velocity_decay/>
        <self_collide>0</self_collide>
        <kinematic>0</kinematic>
      </link>
      <pose frame=''>-0.15 0.15 0 0 -0 0</pose>
    </model>
    <model name='camera'>
      <link name='base_link'>
        <pose frame=''>0 0 0 0 -0 0</pose>
        <inertial>
          <pose frame=''>0 0 0 0 -0 0</pose>
          <mass>0.0458</mass>
          <inertia>
            <ixx>2.4e-05</ixx>
            <ixy>0</ixy>
            <ixz>0</ixz>
            <iyy>2.4e-05</iyy>
            <iyz>0</iyz>
            <izz>2.4e-05</izz>
          </inertia>
        </inertial>
        <collision name='base_link_fixed_joint_lump__camera_link_collision'>
          <pose frame=''>0 0 0 3.14159 1.57079 3.14159</pose>
          <geometry>
            <box>
              <size>0.02 0.02 0.04</size>
            </box>
          </geometry>
          <surface>
            <contact>
              <ode/>
            </contact>
            <friction>
              <ode/>
              <torsional>
                <ode/>
              </torsional>
            </friction>
            <bounce/>
          </surface>
          <max_contacts>10</max_contacts>
        </collision>
        <visual name='base_link_fixed_joint_lump__camera_link_visual'>
          <pose frame=''>0 0 0 3.14159 1.57079 3.14159</pose>
          <geometry>
            <box>
              <size>0.02 0.02 0.04</size>
            </box>
          </geometry>
          <material>
            <script>
              <uri>__default__</uri>
              <name>__default__</name>
            </script>
          </material>
        </visual>
        <velocity_decay/>
        <gravity>0</gravity>
        <velocity_decay/>
        <self_collide>0</self_collide>
        <sensor name='camera1' type='camera'>
          <update_rate>30</update_rate>
          <camera name='head'>
            <horizontal_fov>0.883346</horizontal_fov>
            <image>
              <width>640</width>
              <height>480</height>
              <format>R8G8B8</format>
            </image>
            <clip>
              <near>0.02</near>
              <far>300</far>
            </clip>
            <noise>
              <type>gaussian</type>
              <mean>0</mean>
              <stddev>0.007</stddev>
            </noise>
          </camera>
          <plugin name='camera_controller' filename='libgazebo_ros_camera.so'>
            <alwaysOn>true</alwaysOn>
            <updateRate>0.0</updateRate>
            <cameraName>cv_camera_node</cameraName>
            <imageTopicName>image_raw</imageTopicName>
            <cameraInfoTopicName>camera_info</cameraInfoTopicName>
            <frameName>camera_link</frameName>
            <hackBaseline>0.07</hackBaseline>
            <distortionK1>0.0</distortionK1>
            <distortionK2>0.0</distortionK2>
            <distortionK3>0.0</distortionK3>
            <distortionT1>0.0</distortionT1>
            <distortionT2>0.0</distortionT2>
            <robotNamespace>/</robotNamespace>
          </plugin>
          <pose frame=''>0 0 0 3.14159 1.57079 3.14159</pose>
        </sensor>
        <kinematic>0</kinematic>
      </link>
      <pose frame=''>0.29 0.105 0.92 0 -0 0</pose>
    </model>
    <model name='beer'>
      <link name='link'>
        <pose frame=''>0 0 0.115 0 -0 0</pose>
        <inertial>
          <mass>0.39</mass>
          <inertia>
            <ixx>0.00058</ixx>
            <ixy>0</ixy>
            <ixz>0</ixz>
            <iyy>0.00058</iyy>
            <iyz>0</iyz>
            <izz>0.00019</izz>
          </inertia>
        </inertial>
        <collision name='collision'>
          <geometry>
            <cylinder>
              <radius>0.055</radius>
              <length>0.23</length>
            </cylinder>
          </geometry>
          <max_contacts>10</max_contacts>
          <surface>
            <contact>
              <ode/>
            </contact>
            <bounce/>
            <friction>
              <torsional>
                <ode/>
              </torsional>
              <ode/>
            </friction>
          </surface>
        </collision>
        <visual name='visual'>
          <geometry>
            <cylinder>
              <radius>0.055</radius>
              <length>0.23</length>
            </cylinder>
          </geometry>
          <material>
            <script>
              <uri>model://beer/materials/scripts</uri>
              <uri>model://beer/materials/textures</uri>
              <name>Beer/Diffuse</name>
            </script>
          </material>
        </visual>
        <self_collide>0</self_collide>
        <kinematic>0</kinematic>
        <gravity>1</gravity>
      </link>
      <pose frame=''>0.165268 0.299984 0 0 -0 0</pose>
    </model>
    <state world_name='default'>
      <sim_time>512 88000000</sim_time>
      <real_time>519 274537964</real_time>
      <wall_time>1636836192 458677347</wall_time>
      <iterations>512088</iterations>
      <model name='beer'>
        <pose frame=''>0.165268 0.299984 -2e-06 1e-06 -0 -1e-06</pose>
        <scale>1 1 1</scale>
        <link name='link'>
          <pose frame=''>0.165268 0.299984 0.114998 1e-06 -0 -1e-06</pose>
          <velocity>0 0 0 0 -0 0</velocity>
          <acceleration>0 0 -9.8 0 -0 0</acceleration>
          <wrench>0 0 -3.822 0 -0 0</wrench>
        </link>
      </model>
      <model name='camera'>
        <pose frame=''>0.29 0.105 0.92 0 -0 0</pose>
        <scale>1 1 1</scale>
        <link name='base_link'>
          <pose frame=''>0.29 0.105 0.92 0 -0 0</pose>
          <velocity>0 0 0 0 -0 0</velocity>
          <acceleration>0 0 0 0 -0 0</acceleration>
          <wrench>0 0 0 0 -0 0</wrench>
        </link>
      </model>
      <model name='ground_plane'>
        <pose frame=''>0 0 0 0 -0 0</pose>
        <scale>1 1 1</scale>
        <link name='link'>
          <pose frame=''>0 0 0 0 -0 0</pose>
          <velocity>0 0 0 0 -0 0</velocity>
          <acceleration>0 0 0 0 -0 0</acceleration>
          <wrench>0 0 0 0 -0 0</wrench>
        </link>
      </model>
      <model name='plate'>
        <pose frame=''>-0.15 0.15 0.00499 5.5e-05 -7.1e-05 -0.002966</pose>
        <scale>1 1 1</scale>
        <link name='base_link'>
          <pose frame=''>-0.15 0.15 0.00499 5.5e-05 -7.1e-05 -0.002966</pose>
          <velocity>0 0 0 0 -0 0</velocity>
          <acceleration>0 0 -9.8 0 -0 0</acceleration>
          <wrench>0 0 -0.2205 0 -0 0</wrench>
        </link>
      </model>
      <model name='robot'>
        <pose frame=''>-0.15 0.15 0.01 9e-06 -2.5e-05 -3e-06</pose>
        <scale>1 1 1</scale>
        <link name='base_link'>
          <pose frame=''>-0.15 0.15 0.01 9e-06 -2.5e-05 -3e-06</pose>
          <velocity>2e-06 -3e-06 0 0.000653 0.000161 -0.006019</velocity>
          <acceleration>0.003618 -0.005411 0.000613 1.20406 0.298383 1.35758</acceleration>
          <wrench>0.007236 -0.010822 0.001227 0 -0 0</wrench>
        </link>
        <link name='forearm_link'>
          <pose frame=''>-0.067721 0.15482 0.392802 -0.000627 1.49161 -0.279871</pose>
          <velocity>0.0011 0.00013 -0.000314 -0.000843 0.004864 -0.002597</velocity>
          <acceleration>1.06539 -0.128218 -0.786688 -2.67406 -0.894391 -1.557</acceleration>
          <wrench>1.34239 -0.161555 -0.991227 0 -0 0</wrench>
        </link>
        <link name='shoulder_link'>
          <pose frame=''>-0.150004 0.15 0.1619 -3.2e-05 3.9e-05 -0.279254</pose>
          <velocity>-7.3e-05 5.2e-05 0 -0.001677 -0.000574 -0.004197</velocity>
          <acceleration>-0.073049 0.052334 -0.000416 -1.6775 -0.574064 2.08616</acceleration>
          <wrench>-0.146098 0.104668 -0.000832 0 -0 0</wrench>
        </link>
        <link name='upper_arm_link'>
          <pose frame=''>-0.116981 0.265159 0.161894 -5.6e-05 0.324857 -0.279266</pose>
          <velocity>0.000388 -3.1e-05 -0.000176 -0.000821 0.004378 -0.00287</velocity>
          <acceleration>0.862624 -0.043951 -0.330665 1.60973 -1.44005 -0.325077</acceleration>
          <wrench>2.95017 -0.150313 -1.13087 0 -0 0</wrench>
        </link>
        <link name='vacuum_gripper'>
          <pose frame=''>0.288473 0.137045 0.265145 -3.11315 -0.019493 1.15554</pose>
          <velocity>5e-06 -0.000506 -0.002385 -0.00077 0.007234 -0.001787</velocity>
          <acceleration>0.004866 -0.506267 -2.38469 -0.770184 0.950413 -1.78696</acceleration>
          <wrench>0 -5.1e-05 -0.000238 0 -0 0</wrench>
        </link>
        <link name='wrist_1_link'>
          <pose frame=''>0.136627 0.096227 0.409669 -3.13946 1.54527 2.86448</pose>
          <velocity>0.000966 -0.000325 -0.001264 -0.000208 0.007117 -0.002225</velocity>
          <acceleration>1.14747 -0.376709 -1.44775 -0.060125 0.791393 -2.40538</acceleration>
          <wrench>0.917977 -0.301367 -1.1582 0 -0 0</wrench>
        </link>
        <link name='wrist_2_link'>
          <pose frame=''>0.160069 0.177982 0.409663 -1.59634 0.023151 -1.85063</pose>
          <velocity>0.001145 -0.000317 -0.001469 -0.00031 0.007292 -0.001832</velocity>
          <acceleration>1.08566 -0.467416 -2.06026 -0.151228 0.963155 -1.98077</acceleration>
          <wrench>0.86853 -0.373932 -1.64821 0 -0 0</wrench>
        </link>
        <link name='wrist_3_link'>
          <pose frame=''>0.242086 0.154465 0.407483 -1.59029 -0.02843 2.72689</pose>
          <velocity>0.00107 -0.000327 -0.002059 -0.000771 0.007248 -0.001823</velocity>
          <acceleration>0.624403 -0.372788 -2.05211 2.37932 -0.08873 1.82455</acceleration>
          <wrench>0.218603 -0.130513 -0.718445 0 -0 0</wrench>
        </link>
      </model>
      <light name='sun'>
        <pose frame=''>0 0 10 0 -0 0</pose>
      </light>
    </state>
    <gui fullscreen='0'>
      <camera name='user_camera'>
        <pose frame=''>0.93157 -0.747669 0.565604 0 0.275643 2.35619</pose>
        <view_controller>orbit</view_controller>
        <projection_type>perspective</projection_type>
      </camera>
    </gui>
  </world>
</sdf>
